{
 "cells": [
  {
   "cell_type": "markdown",
   "id": "40b0351a",
   "metadata": {},
   "source": [
    "# Notebook to Create Database"
   ]
  },
  {
   "cell_type": "code",
   "execution_count": null,
   "id": "0b7b1735",
   "metadata": {},
   "outputs": [
    {
     "name": "stderr",
     "output_type": "stream",
     "text": [
      "ERROR:root:Internal Python error in the inspect module.\n",
      "Below is the traceback from this internal error.\n",
      "\n",
      "ERROR:root:Internal Python error in the inspect module.\n",
      "Below is the traceback from this internal error.\n",
      "\n",
      "ERROR:root:Internal Python error in the inspect module.\n",
      "Below is the traceback from this internal error.\n",
      "\n"
     ]
    },
    {
     "name": "stdout",
     "output_type": "stream",
     "text": [
      "Traceback (most recent call last):\n",
      "  File \"/opt/anaconda3/lib/python3.9/site-packages/IPython/core/interactiveshell.py\", line 3457, in run_code\n",
      "    exec(code_obj, self.user_global_ns, self.user_ns)\n",
      "  File \"/var/folders/zk/y1x3sh6d4lbbx6qg8qx5q0j80000gn/T/ipykernel_62777/1229511693.py\", line 2, in <module>\n",
      "    import pandas as pd\n",
      "  File \"<frozen importlib._bootstrap>\", line 1007, in _find_and_load\n",
      "  File \"<frozen importlib._bootstrap>\", line 982, in _find_and_load_unlocked\n",
      "  File \"<frozen importlib._bootstrap>\", line 925, in _find_spec\n",
      "  File \"<frozen importlib._bootstrap_external>\", line 1423, in find_spec\n",
      "  File \"<frozen importlib._bootstrap_external>\", line 1392, in _get_spec\n",
      "  File \"<frozen importlib._bootstrap_external>\", line 1356, in _path_importer_cache\n",
      "PermissionError: [Errno 1] Operation not permitted\n",
      "\n",
      "During handling of the above exception, another exception occurred:\n",
      "\n",
      "Traceback (most recent call last):\n",
      "  File \"/opt/anaconda3/lib/python3.9/site-packages/IPython/core/interactiveshell.py\", line 2077, in showtraceback\n",
      "    stb = value._render_traceback_()\n",
      "AttributeError: 'PermissionError' object has no attribute '_render_traceback_'\n",
      "\n",
      "During handling of the above exception, another exception occurred:\n",
      "\n",
      "Traceback (most recent call last):\n",
      "  File \"/opt/anaconda3/lib/python3.9/site-packages/IPython/core/ultratb.py\", line 1101, in get_records\n",
      "    return _fixed_getinnerframes(etb, number_of_lines_of_context, tb_offset)\n",
      "  File \"/opt/anaconda3/lib/python3.9/site-packages/IPython/core/ultratb.py\", line 248, in wrapped\n",
      "    return f(*args, **kwargs)\n",
      "  File \"/opt/anaconda3/lib/python3.9/site-packages/IPython/core/ultratb.py\", line 281, in _fixed_getinnerframes\n",
      "    records = fix_frame_records_filenames(inspect.getinnerframes(etb, context))\n",
      "  File \"/opt/anaconda3/lib/python3.9/inspect.py\", line 1543, in getinnerframes\n",
      "    frameinfo = (tb.tb_frame,) + getframeinfo(tb, context)\n",
      "  File \"/opt/anaconda3/lib/python3.9/inspect.py\", line 1501, in getframeinfo\n",
      "    filename = getsourcefile(frame) or getfile(frame)\n",
      "  File \"/opt/anaconda3/lib/python3.9/inspect.py\", line 709, in getsourcefile\n",
      "    if getattr(getmodule(object, filename), '__loader__', None) is not None:\n",
      "  File \"/opt/anaconda3/lib/python3.9/inspect.py\", line 738, in getmodule\n",
      "    file = getabsfile(object, _filename)\n",
      "  File \"/opt/anaconda3/lib/python3.9/inspect.py\", line 722, in getabsfile\n",
      "    return os.path.normcase(os.path.abspath(_filename))\n",
      "  File \"/opt/anaconda3/lib/python3.9/posixpath.py\", line 380, in abspath\n",
      "    cwd = os.getcwd()\n",
      "PermissionError: [Errno 1] Operation not permitted\n",
      "Traceback (most recent call last):\n",
      "  File \"/opt/anaconda3/lib/python3.9/site-packages/IPython/core/interactiveshell.py\", line 3457, in run_code\n",
      "    exec(code_obj, self.user_global_ns, self.user_ns)\n",
      "  File \"/var/folders/zk/y1x3sh6d4lbbx6qg8qx5q0j80000gn/T/ipykernel_62777/1229511693.py\", line 2, in <module>\n",
      "    import pandas as pd\n",
      "  File \"<frozen importlib._bootstrap>\", line 1007, in _find_and_load\n",
      "  File \"<frozen importlib._bootstrap>\", line 982, in _find_and_load_unlocked\n",
      "  File \"<frozen importlib._bootstrap>\", line 925, in _find_spec\n",
      "  File \"<frozen importlib._bootstrap_external>\", line 1423, in find_spec\n",
      "  File \"<frozen importlib._bootstrap_external>\", line 1392, in _get_spec\n",
      "  File \"<frozen importlib._bootstrap_external>\", line 1356, in _path_importer_cache\n",
      "PermissionError: [Errno 1] Operation not permitted\n",
      "\n",
      "During handling of the above exception, another exception occurred:\n",
      "\n",
      "Traceback (most recent call last):\n",
      "  File \"/opt/anaconda3/lib/python3.9/site-packages/IPython/core/interactiveshell.py\", line 2077, in showtraceback\n",
      "    stb = value._render_traceback_()\n",
      "AttributeError: 'PermissionError' object has no attribute '_render_traceback_'\n",
      "\n",
      "During handling of the above exception, another exception occurred:\n",
      "\n",
      "Traceback (most recent call last):\n",
      "  File \"/opt/anaconda3/lib/python3.9/site-packages/IPython/core/interactiveshell.py\", line 3377, in run_ast_nodes\n",
      "    if (await self.run_code(code, result,  async_=asy)):\n",
      "  File \"/opt/anaconda3/lib/python3.9/site-packages/IPython/core/interactiveshell.py\", line 3474, in run_code\n",
      "    self.showtraceback(running_compiled_code=True)\n",
      "  File \"/opt/anaconda3/lib/python3.9/site-packages/IPython/core/interactiveshell.py\", line 2079, in showtraceback\n",
      "    stb = self.InteractiveTB.structured_traceback(etype,\n",
      "  File \"/opt/anaconda3/lib/python3.9/site-packages/IPython/core/ultratb.py\", line 1367, in structured_traceback\n",
      "    return FormattedTB.structured_traceback(\n",
      "  File \"/opt/anaconda3/lib/python3.9/site-packages/IPython/core/ultratb.py\", line 1267, in structured_traceback\n",
      "    return VerboseTB.structured_traceback(\n",
      "  File \"/opt/anaconda3/lib/python3.9/site-packages/IPython/core/ultratb.py\", line 1124, in structured_traceback\n",
      "    formatted_exception = self.format_exception_as_a_whole(etype, evalue, etb, number_of_lines_of_context,\n",
      "  File \"/opt/anaconda3/lib/python3.9/site-packages/IPython/core/ultratb.py\", line 1082, in format_exception_as_a_whole\n",
      "    last_unique, recursion_repeat = find_recursion(orig_etype, evalue, records)\n",
      "  File \"/opt/anaconda3/lib/python3.9/site-packages/IPython/core/ultratb.py\", line 382, in find_recursion\n",
      "    return len(records), 0\n",
      "TypeError: object of type 'NoneType' has no len()\n",
      "\n",
      "During handling of the above exception, another exception occurred:\n",
      "\n",
      "Traceback (most recent call last):\n",
      "  File \"/opt/anaconda3/lib/python3.9/site-packages/IPython/core/interactiveshell.py\", line 2077, in showtraceback\n",
      "    stb = value._render_traceback_()\n",
      "AttributeError: 'TypeError' object has no attribute '_render_traceback_'\n",
      "\n",
      "During handling of the above exception, another exception occurred:\n",
      "\n",
      "Traceback (most recent call last):\n",
      "  File \"/opt/anaconda3/lib/python3.9/site-packages/IPython/core/ultratb.py\", line 1101, in get_records\n",
      "    return _fixed_getinnerframes(etb, number_of_lines_of_context, tb_offset)\n",
      "  File \"/opt/anaconda3/lib/python3.9/site-packages/IPython/core/ultratb.py\", line 248, in wrapped\n",
      "    return f(*args, **kwargs)\n",
      "  File \"/opt/anaconda3/lib/python3.9/site-packages/IPython/core/ultratb.py\", line 281, in _fixed_getinnerframes\n",
      "    records = fix_frame_records_filenames(inspect.getinnerframes(etb, context))\n",
      "  File \"/opt/anaconda3/lib/python3.9/inspect.py\", line 1543, in getinnerframes\n",
      "    frameinfo = (tb.tb_frame,) + getframeinfo(tb, context)\n",
      "  File \"/opt/anaconda3/lib/python3.9/inspect.py\", line 1501, in getframeinfo\n",
      "    filename = getsourcefile(frame) or getfile(frame)\n",
      "  File \"/opt/anaconda3/lib/python3.9/inspect.py\", line 709, in getsourcefile\n",
      "    if getattr(getmodule(object, filename), '__loader__', None) is not None:\n",
      "  File \"/opt/anaconda3/lib/python3.9/inspect.py\", line 738, in getmodule\n",
      "    file = getabsfile(object, _filename)\n",
      "  File \"/opt/anaconda3/lib/python3.9/inspect.py\", line 722, in getabsfile\n",
      "    return os.path.normcase(os.path.abspath(_filename))\n",
      "  File \"/opt/anaconda3/lib/python3.9/posixpath.py\", line 380, in abspath\n",
      "    cwd = os.getcwd()\n",
      "PermissionError: [Errno 1] Operation not permitted\n",
      "Traceback (most recent call last):\n",
      "  File \"/opt/anaconda3/lib/python3.9/site-packages/IPython/core/interactiveshell.py\", line 3457, in run_code\n",
      "    exec(code_obj, self.user_global_ns, self.user_ns)\n",
      "  File \"/var/folders/zk/y1x3sh6d4lbbx6qg8qx5q0j80000gn/T/ipykernel_62777/1229511693.py\", line 2, in <module>\n",
      "    import pandas as pd\n",
      "  File \"<frozen importlib._bootstrap>\", line 1007, in _find_and_load\n",
      "  File \"<frozen importlib._bootstrap>\", line 982, in _find_and_load_unlocked\n",
      "  File \"<frozen importlib._bootstrap>\", line 925, in _find_spec\n",
      "  File \"<frozen importlib._bootstrap_external>\", line 1423, in find_spec\n",
      "  File \"<frozen importlib._bootstrap_external>\", line 1392, in _get_spec\n",
      "  File \"<frozen importlib._bootstrap_external>\", line 1356, in _path_importer_cache\n",
      "PermissionError: [Errno 1] Operation not permitted\n",
      "\n",
      "During handling of the above exception, another exception occurred:\n",
      "\n",
      "Traceback (most recent call last):\n",
      "  File \"/opt/anaconda3/lib/python3.9/site-packages/IPython/core/interactiveshell.py\", line 2077, in showtraceback\n",
      "    stb = value._render_traceback_()\n",
      "AttributeError: 'PermissionError' object has no attribute '_render_traceback_'\n",
      "\n",
      "During handling of the above exception, another exception occurred:\n",
      "\n",
      "Traceback (most recent call last):\n",
      "  File \"/opt/anaconda3/lib/python3.9/site-packages/IPython/core/interactiveshell.py\", line 3377, in run_ast_nodes\n",
      "    if (await self.run_code(code, result,  async_=asy)):\n",
      "  File \"/opt/anaconda3/lib/python3.9/site-packages/IPython/core/interactiveshell.py\", line 3474, in run_code\n",
      "    self.showtraceback(running_compiled_code=True)\n",
      "  File \"/opt/anaconda3/lib/python3.9/site-packages/IPython/core/interactiveshell.py\", line 2079, in showtraceback\n",
      "    stb = self.InteractiveTB.structured_traceback(etype,\n",
      "  File \"/opt/anaconda3/lib/python3.9/site-packages/IPython/core/ultratb.py\", line 1367, in structured_traceback\n",
      "    return FormattedTB.structured_traceback(\n",
      "  File \"/opt/anaconda3/lib/python3.9/site-packages/IPython/core/ultratb.py\", line 1267, in structured_traceback\n",
      "    return VerboseTB.structured_traceback(\n",
      "  File \"/opt/anaconda3/lib/python3.9/site-packages/IPython/core/ultratb.py\", line 1124, in structured_traceback\n",
      "    formatted_exception = self.format_exception_as_a_whole(etype, evalue, etb, number_of_lines_of_context,\n",
      "  File \"/opt/anaconda3/lib/python3.9/site-packages/IPython/core/ultratb.py\", line 1082, in format_exception_as_a_whole\n",
      "    last_unique, recursion_repeat = find_recursion(orig_etype, evalue, records)\n",
      "  File \"/opt/anaconda3/lib/python3.9/site-packages/IPython/core/ultratb.py\", line 382, in find_recursion\n",
      "    return len(records), 0\n",
      "TypeError: object of type 'NoneType' has no len()\n",
      "\n",
      "During handling of the above exception, another exception occurred:\n",
      "\n",
      "Traceback (most recent call last):\n",
      "  File \"/opt/anaconda3/lib/python3.9/site-packages/IPython/core/interactiveshell.py\", line 2077, in showtraceback\n",
      "    stb = value._render_traceback_()\n",
      "AttributeError: 'TypeError' object has no attribute '_render_traceback_'\n",
      "\n",
      "During handling of the above exception, another exception occurred:\n",
      "\n",
      "Traceback (most recent call last):\n",
      "  File \"/opt/anaconda3/lib/python3.9/site-packages/IPython/core/interactiveshell.py\", line 2960, in _run_cell\n",
      "    return runner(coro)\n",
      "  File \"/opt/anaconda3/lib/python3.9/site-packages/IPython/core/async_helpers.py\", line 78, in _pseudo_sync_runner\n",
      "    coro.send(None)\n",
      "  File \"/opt/anaconda3/lib/python3.9/site-packages/IPython/core/interactiveshell.py\", line 3185, in run_cell_async\n",
      "    has_raised = await self.run_ast_nodes(code_ast.body, cell_name,\n",
      "  File \"/opt/anaconda3/lib/python3.9/site-packages/IPython/core/interactiveshell.py\", line 3396, in run_ast_nodes\n",
      "    self.showtraceback()\n",
      "  File \"/opt/anaconda3/lib/python3.9/site-packages/IPython/core/interactiveshell.py\", line 2079, in showtraceback\n",
      "    stb = self.InteractiveTB.structured_traceback(etype,\n",
      "  File \"/opt/anaconda3/lib/python3.9/site-packages/IPython/core/ultratb.py\", line 1367, in structured_traceback\n",
      "    return FormattedTB.structured_traceback(\n",
      "  File \"/opt/anaconda3/lib/python3.9/site-packages/IPython/core/ultratb.py\", line 1267, in structured_traceback\n",
      "    return VerboseTB.structured_traceback(\n",
      "  File \"/opt/anaconda3/lib/python3.9/site-packages/IPython/core/ultratb.py\", line 1142, in structured_traceback\n",
      "    formatted_exceptions += self.format_exception_as_a_whole(etype, evalue, etb, lines_of_context,\n",
      "  File \"/opt/anaconda3/lib/python3.9/site-packages/IPython/core/ultratb.py\", line 1082, in format_exception_as_a_whole\n",
      "    last_unique, recursion_repeat = find_recursion(orig_etype, evalue, records)\n",
      "  File \"/opt/anaconda3/lib/python3.9/site-packages/IPython/core/ultratb.py\", line 382, in find_recursion\n",
      "    return len(records), 0\n",
      "TypeError: object of type 'NoneType' has no len()\n",
      "\n",
      "During handling of the above exception, another exception occurred:\n",
      "\n",
      "Traceback (most recent call last):\n",
      "  File \"/opt/anaconda3/lib/python3.9/site-packages/IPython/core/interactiveshell.py\", line 2077, in showtraceback\n",
      "    stb = value._render_traceback_()\n",
      "AttributeError: 'TypeError' object has no attribute '_render_traceback_'\n",
      "\n",
      "During handling of the above exception, another exception occurred:\n",
      "\n",
      "Traceback (most recent call last):\n",
      "  File \"/opt/anaconda3/lib/python3.9/site-packages/IPython/core/ultratb.py\", line 1101, in get_records\n",
      "    return _fixed_getinnerframes(etb, number_of_lines_of_context, tb_offset)\n",
      "  File \"/opt/anaconda3/lib/python3.9/site-packages/IPython/core/ultratb.py\", line 248, in wrapped\n",
      "    return f(*args, **kwargs)\n",
      "  File \"/opt/anaconda3/lib/python3.9/site-packages/IPython/core/ultratb.py\", line 281, in _fixed_getinnerframes\n",
      "    records = fix_frame_records_filenames(inspect.getinnerframes(etb, context))\n",
      "  File \"/opt/anaconda3/lib/python3.9/inspect.py\", line 1543, in getinnerframes\n",
      "    frameinfo = (tb.tb_frame,) + getframeinfo(tb, context)\n",
      "  File \"/opt/anaconda3/lib/python3.9/inspect.py\", line 1501, in getframeinfo\n",
      "    filename = getsourcefile(frame) or getfile(frame)\n",
      "  File \"/opt/anaconda3/lib/python3.9/inspect.py\", line 709, in getsourcefile\n",
      "    if getattr(getmodule(object, filename), '__loader__', None) is not None:\n",
      "  File \"/opt/anaconda3/lib/python3.9/inspect.py\", line 738, in getmodule\n",
      "    file = getabsfile(object, _filename)\n",
      "  File \"/opt/anaconda3/lib/python3.9/inspect.py\", line 722, in getabsfile\n",
      "    return os.path.normcase(os.path.abspath(_filename))\n",
      "  File \"/opt/anaconda3/lib/python3.9/posixpath.py\", line 380, in abspath\n",
      "    cwd = os.getcwd()\n",
      "PermissionError: [Errno 1] Operation not permitted\n"
     ]
    }
   ],
   "source": [
    "import sqlite3\n",
    "import pandas as pd"
   ]
  },
  {
   "cell_type": "markdown",
   "id": "395e8f32",
   "metadata": {},
   "source": [
    "Create a database and connect"
   ]
  },
  {
   "cell_type": "code",
   "execution_count": null,
   "id": "3b983edb",
   "metadata": {},
   "outputs": [],
   "source": [
    "conn = sqlite3.connect('renewable_spain.db')\n",
    "c = conn.cursor()"
   ]
  },
  {
   "cell_type": "markdown",
   "id": "518b2be9",
   "metadata": {},
   "source": [
    "Connect to the raw data table"
   ]
  },
  {
   "cell_type": "code",
   "execution_count": null,
   "id": "69ebb093",
   "metadata": {},
   "outputs": [],
   "source": [
    "read_raw = pd.read_csv(r'raw_data/energy_dataset.csv')\n",
    "read_raw.to_sql('energy_dataset', conn, if_exists='append',index = False')"
   ]
  },
  {
   "cell_type": "markdown",
   "id": "0d19a22e",
   "metadata": {},
   "source": [
    "Create time_stamp table and add timestamps with index as primary key"
   ]
  },
  {
   "cell_type": "code",
   "execution_count": null,
   "id": "14879463",
   "metadata": {},
   "outputs": [],
   "source": [
    "c.execute('''\n",
    "CREATE TABLE time_stamps (\n",
    "row int PRIMARY KEY,\n",
    "time text,\n",
    ") [WITHOUT ROWID];\n",
    "''')\n",
    "c.execute('''INSERT INTO time_stamps SELECT time FROM energy_dataset''')\n",
    "index = 0\n",
    "for row in c.execute('''SELECT * FROM time_stamps''')\n",
    "    c.execute('''UPDATE time_stamps SET row = ?''', index)\n",
    "    index += 1\n"
   ]
  }
 ],
 "metadata": {
  "kernelspec": {
   "display_name": "Python 3 (ipykernel)",
   "language": "python",
   "name": "python3"
  },
  "language_info": {
   "codemirror_mode": {
    "name": "ipython",
    "version": 3
   },
   "file_extension": ".py",
   "mimetype": "text/x-python",
   "name": "python",
   "nbconvert_exporter": "python",
   "pygments_lexer": "ipython3",
   "version": "3.9.13"
  }
 },
 "nbformat": 4,
 "nbformat_minor": 5
}
